Workbook
Name Divisor: BaseDivisores[Descrição]
Name Divisoria_Ambiente: BaseAmbientes[Descrição]
Name Extra: BaseExtra[Item]
Name Furos: BaseOutros[Item]
Name Perfil: BasePerfis[Descrição]
Name Perfil_Puxador: BasePerfilPuxadores[Descrição]
Name Puxador: BasePuxadores[Descrição]
Name Vidros: BaseVidros[Descrição]

Sheet PERFIl
A1: Codigo | B1: Descrição | C1: Preço
A2: 17914 | B2: Perfil DES-1934 Preto (3025) | C2: 36.25
A3: 17695 | B3: Perfil DES-1934 Anod (3025) | C3: 35.6
A4: 18058 | B4: Perfil DES-1934 Esc (3025) | C4: 42.95
A5: 010562 | B5: Perfil 3025 Anodizado (3025) | C5: 49.9
A6: 015490 | B6: Perfil 3025 Branco (3025) | C6: 58.75
A7: 015525 | B7: Perfil 3025 Dourado (3025) | C7: 55.9
A8: 5002 | B8: Perfil 3025 Inox Esc (3025) | C8: 58.3
A9: 014584 | B9: Perfil 3025 Preto (3025) | C9: 51
A10: 16535 | B10: Perfil 3026 Anodizado | C10: 58.5
A11: 17611 | B11: Perfil 3026 Inox Esc | C11: 65.25
A12: 16499 | B12: Perfil 3026 Preto | C12: 67.2
A13: 011131 | B13: Perfil 3044 Inox Escovado (3044) | C13: 49.245
A14: 002467 | B14: Perfil 3044 Preto (3044) | C14: 31.5
A15: 004482 | B15: Perfil 3136 Anodizado (3136) | C15: 53.4
A16: 003532 | B16: Perfil 3136 Branco (3136) | C16: 56
A17: 000015 | B17: Perfil 3136 Bronze 1001 (3136) | C17: 59
A18: 015523 | B18: Perfil 3136 Dourado (3136) | C18: 68.2
A19: 014259 | B19: Perfil 3136 Inox Escovado (3136) | C19: 72.5
A20: 003497 | B20: Perfil 3136 Preto (3136) | C20: 60.5
A21: 013800 | B21: Perfil 3144 Anodizado | C21: 53.8
A22: 016016 | B22: Perfil 3144 Bronze 1001 | C22: 61.9
A23: 016004 | B23: Perfil 3144 Inox Escovado | C23: 65.65
A24: 000753 | B24: Perfil 3152 Branco Fosco (3152) | C24: 40.5615
... A29: 000639 | B29: Perfil 3345 Inox Escovado (3345) | C29: 80.5
A30: 002466 | B30: Perfil 3345 Inox Fosco (3345) | C30: xxxx
A31: 004991 | B31: Perfil 3345 Preto (3345) | C31: 71.25
A32: 17697 | B32: Perfil DES-147 Anod (3446) | C32: 48.6
A33: 010791 | B33: Perfil 3446 Anodizado (3446) | C33: 75
A34: 004058 | B34: Perfil 3446 Branco (3446) | C34: 66.4
A35: 015468 | B35: Perfil 3446 Bronze 1001 (3446) | C35: 71.9
A36: 002188 | B36: Perfil 3446 Inox Escovado (3446) | C36: 72.26
A37: 004060 | B37: Perfil 3446 Preto (3446) | C37: 82.85
A38: 005106 | B38: Perfil 3447 Anodizado | C38: 55.4
A39: 001762 | B39: Perfil 3470 Anod (3470) Pele de Vidro | C39: 93.45
A40: 009948 | B40: Perfil DES-011 Anodizado (3528) | C40: 85
A41: 012568 | B41: Perfil DES-011 Inox Escovado (3528) | C41: 95.4
A42: 010121 | B42: Perfil DES-016 Anodizado (3060) | C42: 52.7
A43: 012592 | B43: Perfil DES-016 Branco (3060) | C43: 52.8
A44: 012569 | B44: Perfil DES-016 Preto (3060) | C44: 60.3
...

Sheet PERFIL_PUXADOR
A1: Codigo | B1: Descrição | C1: Preço
A2: 004492 | B2: Perfil Puxador 3177T Anodizado (3177T) | C2: 94.9
A3: 004977 | B3: Perfil Puxador 3177T Branco Fosco (3177T) | C3: 111
A4: 002191 | B4: Perfil Puxador 3177T Inox Escovado (3177T) | C4: 110.6
A5: 004984 | B5: Perfil Puxador 3177T Preto Fosco (3177T) | C5: 102.8
A6: 015590 | B6: Perfil Puxador 3178 Dourado (3178) | C6: 107.9
A7: 004500 | B7: Perfil Puxador 3178T Anodizado (3178T) | C7: 58.695
A8: 003498 | B8: Perfil Puxador 3178T Branco Fosco (3178T) | C8: 53.55
A9: 003499 | B9: Perfil Puxador 3178T Preto Fosco (3178T) | C9: 50.1375
A10: 003523 | B10: Perfil Puxador 3180 Anodizado (3180) | C10: 64.1
A11: 007906 | B11: Perfil Puxador 3180 Inox Escovado (3180) | C11: xxxx
A12: 011398 | B12: Perfil Puxador 3180T Branco Fosco (3180T) | C12: 78.225
A13: 011412 | B13: Perfil Puxador 3180T Preto Fosco (3180T) | C13: 84
A14: 004493 | B14: Perfil Puxador 3365 Anodizado (3365) | C14: 59.01
A15: 012558 | B15: Perfil Puxador 3365 Branco (3365) | C15: 76.65
A16: 004495 | B16: Perfil Puxador 3365 Inox Escovado (3365) | C16: 115.15
A17: 012523 | B17: Perfil Puxador 3365 Preto (3365) | C17: 73.8675
A18: 16822 | B18: Perfil Pux 3366 Preto | C18: 80.5
A19: 2189 | B19: Perfil Pux 3366 Escovado | C19: 104.9
A20: 16800 | B20: Perfil Pux 3366 Bronze 1001 | C20: 94.3
A21: 16705 | B21: Perfil Pux 3366 Anodizado | C21: 96
A22: 013799 | B22: Perfil Puxador 4007 Anodizado | C22: 59.6
A23: 013821 | B23: Perfil Puxador 5007 Anodizado 5,3 Mts | C23: 70.8
A24: 016005 | B24: Perfil Puxador 5007 Bronze 1001 5,3 Mts | C24: 78.65
A25: 013993 | B25: Perfil Puxador DES-204 Aluminio Natural (204) | C25: 77.7
A26: 17699 | B26: Perfil Puxador AD-204 Anodizado (204) | C26: 59.9
A27: 009951 | B27: Perfil Puxador DES-204 Anodizado (204) | C27: 79.45
A28: 012762 | B28: Perfil Puxador DES-204 Branco Fosco (204) | C28: 72.15
A29: 011796 | B29: Perfil Puxador DES-204 Bronze 1001 (204) | C29: 88.8
A30: 011659 | B30: Perfil Puxador DES-204 Inox Escovado (204) | C30: 104.06
A31: 012774 | B31: Perfil Puxador DES-204 Preto (204) | C31: 94.79
A32: 004424 | B32: Perfil Puxador DES-225 Anodizado (225) | C32: 84.6
A33: 004149 | B33: Perfil Puxador DES-225 Inox Escovado (225) | C33: 82.85
A34: 016127 | B34: Perfil Puxador DES-225 Preto (225) | C34: 77.7
A35: 003747 | B35: Perfil Puxador DES-227 Anodizado (227) | C35: 72.15
A36: 003748 | B36: Perfil Puxador DES-227 Inox Escovado (227) | C36: 79.14
A37: 016129 | B37: Perfil Puxador DES-227 Preto (227) | C37: 67.65
A38: 003526 | B38: Perfil Puxador DES-950 Anodizado (950) | C38: 83.69
... A46: 004813 | B46: Perfil Puxador Di Vetro 5 Titanium (204 Economico) | C46: 59.75
A47: 15681 | B47: Perfil Puxador DES-950 Alum Natural (950) | C47: 65.83

Sheet PUXADOR
A1: Codigo | B1: Descrição | C1: Preço
A2: 014174 | B2: Puxador 2007 Inox Escovado (2010 - 21,5mm) | C2: 48.1
A3: 014653 | B3: Puxador 2007 Preto (2010 - 21,5mm) | C3: 50.4
A4: 015526 | B4: Puxador 2010 Dourado (2010 - 22,5MM) | C4: 55.9
A5: 005113 | B5: Puxador 2015 Branco Fosco (2015) | C5: 28.98
A6: 015527 | B6: Puxador 2015 Dourado (2015) | C6: 44.25
A7: 006772 | B7: Puxador 2015 Inox Escovado (2015) | C7: 39.6375
A8: 003196 | B8: Puxador 2018E Anodizado (2018E) | C8: 31.5
A9: 003540 | B9: Puxador 2018E Inox Escovado (2018E) | C9: 36.75
A10: 007802 | B10: Puxador 2019 Anodizado (2019) | C10: 33.8
A11: 015869 | B11: Puxador 2019 Branco (2019) | C11: 33.7
A12: 015729 | B12: Puxador 2019 Bronze 1001 (2019) | C12: 35.75
A13: 015524 | B13: Puxador 2019 Dourado (2019) | C13: 44.4
... A45: 014963 | B45: Puxador Versatile AD 001 Preto | C45: 33.85

Sheet DIVISORES
A1: Codigo | B1: Descrição | C1: Preço | D1: Acabamento | E1: Tipo | F1: Modelo
A2: 3191 | B2: 1901 Anodizado (1901) | C2: 33.6 | D2: Anodizado | E2: DIVISORES | F2: 1901
A3: 4056 | B3: 1901 Branco (1901) | C3: 31.08 | D3: Branco | E3: DIVISORES | F3: 1901
A4: 3193 | B4: 1901 Inox Escovado (1901) | C4: 47.25 | D4: Inox Escovado | E4: DIVISORES | F4: 1901
A5: 4057 | B5: 1901 Preto (1901) | C5: 31.08 | D5: Preto | E5: DIVISORES | F5: 1901
A6: 3189 | B6: 1902 Anodizado (1902) | C6: 31.5 | D6: Anodizado | E6: DIVISORES | F6: 1902
A7: 4061 | B7: 1902 Branco (1902) | C7: 31.5 | D7: Branco | E7: DIVISORES | F7: 1902
A8: 3190 | B8: 1902 Inox Escovado (1902) | C8: 36.75 | D8: Inox Escovado | E8: DIVISORES | F8: 1902
A9: 4069 | B9: 1902 Preto (1902) | C9: 31.5 | D9: Preto | E9: DIVISORES | F9: 1902
A10: 17889 | B10: 2004 Largo Anodizado (2004) | C10: 55.3 | D10: Anodizado | E10: DIVISORES | F10: 2004
A11: 7486 | B11: 2003 Anodizado (2003) | C11: 38.0625 | D11: Anodizado | E11: DIVISORES | F11: 2003
A12: 4070 | B12: 2003 Branco (2003) | C12: 42 | D12: Branco | E12: DIVISORES | F12: 2003
A13: 15948 | B13: 2003 Dourado (2003) | C13: 47.9 | D13: Dourado | E13: DIVISORES | F13: 2003
... A25: 12611 | B25: Oculto 3618 Preto (3618) | C25: 33.5 | D25: Preto | E25: DIVISORES | F25: 3618

Sheet DIVISORIA_DE_AMBIENTE
A1: Codigo | B1: Descrição | C1: Preço
A2: 003929 | B2: Perfil Puxador RM-070 Anodizado | C2: 82.4
A3: 003359 | B3: Perfil Puxador RM-070 Inox Escovado | C3: 109
A4: 011405 | B4: Perfil Puxador RM-070 Preto | C4: 96.3
A5: 009265 | B5: Perfil RM-066 Anodizado (Travessa) | C5: 57.8
A6: 003334 | B6: Perfil RM-066 Inox Escovado (Travessa) | C6: 77
A7: 011407 | B7: Perfil RM-066 Preto (Travessa) | C7: 62
A8: 003928 | B8: Perfil RM-069 Anodizado (Travessa Superior) | C8: 61.85
A9: 003354 | B9: Perfil RM-069 Inox Escovado (Travessa Superior) | C9: 114.2
A10: 011406 | B10: Perfil RM-069 Preto (Travessa Superior) | C10: 113.7
A11: 003935 | B11: Perfil RM-201 Anodizado | C11: 74.6
A12: 004131 | B12: Perfil RM-201 Inox Escovado | C12: 84.9
A13: 003360 | B13: Perfil RM-203 Inox Escovado | C13: 86.75
... A17: 003936 | B17: Perfil Trilho Guia RM-200 Anodizado Sequenziato | C17: 27.5

Sheet BASE_VIDROS
A1: Codigo | B1: Descrição | C1: Preço
A2: 000210 | B2: Acidato Bronze 4MM | C2: 418.47
A3: 013024 | B3: Acidato Fume 4MM | C3: 379.62
A4: 008787 | B4: Acidato Prata 4MM | C4: 271.83
A5: 008196 | B5: Argentato Bronze 4MM | C5: 374.84
A6: 000211 | B6: Argentato Fume 4MM | C6: 405.15
A7: 011157 | B7: Argentato Prata 4MM | C7: 407.31
A8: 003801 | B8: Bronze 4MM | C8: 165.61
A9: 004375 | B9: Café 4MM | C9: 0
A10: 18006 | B10: Canelado Mini 4MM | C10: 177.4
A11: 011767 | B11: Canelado Real 3/4MM | C11: 149.8
A12: 001829 | B12: Coverglass Branco 4MM | C12: 201.35
A13: 011351 | B13: Coverglass Preto 4MM | C13: 188.7
A14: 011152 | B14: Espelho Bronze 4MM | C14: 365.19
A15: 000253 | B15: Espelho Fume 4MM | C15: 332
A16: 003183 | B16: Espelho Prata Cebrace | C16: 179.82
A17: 17678 | B17: Espelho Prata Guard. Moveleiro | C17: 149
A18: 003650 | B18: Espelho Prata Guardian | C18: 187.59
A19: 004101 | B19: Extra Branco 4MM | C19: 329.33
A20: 003102 | B20: Extra Clear 4MM | C20: 227.82
A21: 16084 | B21: Extra Clear 6mm | C21: 285.93
A22: 16085 | B22: Extra Clear 8mm | C22: 375
A23: 001240 | B23: Fume 4MM | C23: 133.2
A24: 003065 | B24: Incolor 10MM | C24: 228.66
A25: 006250 | B25: Incolor 4MM | C25: 109
A26: 001106 | B26: Incolor 6MM | C26: 163.4
A27: 003057 | B27: Incolor 8MM | C27: 199.25
A28: 009905 | B28: Mini Boreal Ubv 3/4MM | C28: 142.57
A29: 011815 | B29: Piramide 3/4 | C29: 106.56
A30: 016216 | B30: Pontilhado | C30: 149.4
A31: 003184 | B31: Refletivo Champanhe 4MM | C31: 179.26
A32: 013796 | B32: Refletivo Incolor 4MM | C32: 227.55
A33: 3493 | B33: Vidro Refletivo Habitat Fume 4MM | C33: 221.88

Sheet EXTRAS
A1: Código | B1: Item | C1: Valor | G1: Código | H1: Item | I1: Valor
A2: 1 | B2: Branca Simples | C2: 25 | G2: 1 | H2: Mão de obra Jateado | I2: 50
A3: 2 | B3: Colorida Simples | C3: 90 | G3: 2 | H3: Furo Tomada | I3: 45
A4: 3 | B4: Colorida Premium | C4: 115 | G4: 3 | H4: Furo 8mm a 12mm | I4: 10
A5: 4 | B5: Especiale | C5: 55 | G5: 4 | H5: Furo 15mm a 60mm | I5: 20
A6: 5 | B6: Recouros | C6: 210
A7: 6 | B7: Pintura | C7: 260
A8: 7 | B8: Jato (+ R$ 50,00) | C8: 113
A9: 8 | B9: Redondo | C9: 175
A10: 9 | B10: Só Corte | C10: -5
A11: 10 | B11: Mão de Obra Portas | C11: 60

Sheet Avulso
B3: Planilha de Cálculo para Portas de Alumínio (09/2023)
B4: Perfil | I4: Divisor | N4: Vidros
B5: Cód | C5: Modelo | D5: Valor | E5: Base (m) | F5: Altura (m) | G5: Qtde | H5: Total | I5: Cód. | J5: Modelo | K5: Qt | L5: R$ Lin. | M5: Total | N5: Cód | O5: Modelo | P5: R$ m² | Q5: Total | R5: M²
A6: 39 | B6: =IFERROR(INDEX(PERFIl!$A:$A,MATCH(C6,PERFIl!$B:$B,0)),"") -> 17695 | C6: Perfil DES-1934 Anod (3025) | D6: =IFERROR(VLOOKUP(B6,PERFIl!$A:$C,3,0),"") -> 35.6 | E6: 0.4 | F6: 2 | G6: =((E6*2)+(F6*2)) -> 4.8 | H6: =IFERROR(((E6*2)+(F6*2))*(D6),"") -> 170.88 | I6: =IFERROR(INDEX(DIVISORES!$A:$A,MATCH(J6,DIVISORES!$B:$B,0)),"") | K6: 1 | L6: =IFERROR(VLOOKUP(I6,BaseDivisores[[Codigo]:[Preço]],3,0),"") | M6: =IFERROR((E6*K6*L6),"") | N6: =IFERROR(INDEX(BASE_VIDROS!$A:$A,MATCH(O6,BASE_VIDROS!$B:$B,0)),"") -> 006250 | O6: Incolor 4MM | P6: =IFERROR(VLOOKUP(N6,BaseVidros[[Codigo]:[Preço]],3,0),"") -> 109 | Q6: =IFERROR(E6*F6*P6,"") -> 87.2 | R6: =E6*F6 -> 0.8
A7: 57 | B7: =IFERROR(INDEX(PERFIl!$A:$A,MATCH(C7,PERFIl!$B:$B,0)),"") -> 010051 | C7: Perfil DES-198 Anodizado (3579) | D7: =IFERROR(VLOOKUP(B7,PERFIl!$A:$C,3,0),"") -> 54.75 | E7: 0.35 | F7: 2.1 | G7: =((E7*2)+(F7*2)) -> 4.9 | H7: =IFERROR(((E7*2)+(F7*2))*(D7),"") -> 268.275 | I7: =IFERROR(INDEX(DIVISORES!$A:$A,MATCH(J7,DIVISORES!$B:$B,0)),"") | K7: 1 | L7: =IFERROR(VLOOKUP(I7,BaseDivisores[[Codigo]:[Preço]],3,0),"") | M7: =IFERROR((E7*K7*L7),"") | N7: =IFERROR(INDEX(BASE_VIDROS!$A:$A,MATCH(O7,BASE_VIDROS!$B:$B,0)),"") -> 003801 | O7: Bronze 4MM | P7: =IFERROR(VLOOKUP(N7,BaseVidros[[Codigo]:[Preço]],3,0),"") -> 165.61 | Q7: =IFERROR(E7*F7*P7,"") -> 121.72335 | R7: =E7*F7 -> 0.735
A8: 57 | B8: =IFERROR(INDEX(PERFIl!$A:$A,MATCH(C8,PERFIl!$B:$B,0)),"") -> 011277 | C8: Perfil DES-198 Inox Escovado (3579) | D8: =IFERROR(VLOOKUP(B8,PERFIl!$A:$C,3,0),"") -> 63.7 | E8: 0.49 | F8: 2.459 | G8: =((E8*2)+(F8*2)) -> 5.898 | H8: =IFERROR(((E8*2)+(F8*2))*(D8),"") -> 375.7026 | I8: =IFERROR(INDEX(DIVISORES!$A:$A,MATCH(J8,DIVISORES!$B:$B,0)),"") | K8: 1 | L8: =IFERROR(VLOOKUP(I8,BaseDivisores[[Codigo]:[Preço]],3,0),"") | M8: =IFERROR((E8*K8*L8),"") | N8: =IFERROR(INDEX(BASE_VIDROS!$A:$A,MATCH(O8,BASE_VIDROS!$B:$B,0)),"") -> 003184 | O8: Refletivo Champanhe 4MM | P8: =IFERROR(VLOOKUP(N8,BaseVidros[[Codigo]:[Preço]],3,0),"") -> 179.26 | Q8: =IFERROR(E8*F8*P8,"") -> 215.99217 | R8: =E8*F8 -> 1.20491
A9: 57 | B9: =IFERROR(INDEX(PERFIl!$A:$A,MATCH(C9,PERFIl!$B:$B,0)),"") -> 014259 | C9: Perfil 3136 Inox Escovado (3136) | D9: =IFERROR(VLOOKUP(B9,PERFIl!$A:$C,3,0),"") -> 72.5 | E9: 0.511 | F9: 2.459 | G9: =((E9*2)+(F9*2)) -> 5.94 | H9: =IFERROR(((E9*2)+(F9*2))*(D9),"") -> 430.65 | I9: =IFERROR(INDEX(DIVISORES!$A:$A,MATCH(J9,DIVISORES!$B:$B,0)),"") | K9: 1 | L9: =IFERROR(VLOOKUP(I9,BaseDivisores[[Codigo]:[Preço]],3,0),"") | M9: =IFERROR((E9*K9*L9),"") | N9: =IFERROR(INDEX(BASE_VIDROS!$A:$A,MATCH(O9,BASE_VIDROS!$B:$B,0)),"") -> 003184 | O9: Refletivo Champanhe 4MM | P9: =IFERROR(VLOOKUP(N9,BaseVidros[[Codigo]:[Preço]],3,0),"") -> 179.26 | Q9: =IFERROR(E9*F9*P9,"") -> 225.24897 | R9: =E9*F9 -> 1.256549
A10: 57 | B10: =IFERROR(INDEX(PERFIl!$A:$A,MATCH(C10,PERFIl!$B:$B,0)),"") -> 17695 | C10: Perfil DES-1934 Anod (3025) | D10: =IFERROR(VLOOKUP(B10,PERFIl!$A:$C,3,0),"") -> 35.6 | E10: 0.266 | F10: 2.459 | G10: =((E10*2)+(F10*2)) -> 5.45 | H10: =IFERROR(((E10*2)+(F10*2))*(D10),"") -> 194.02 | I10: =IFERROR(INDEX(DIVISORES!$A:$A,MATCH(J10,DIVISORES!$B:$B,0)),"") | K10: 1 | L10: =IFERROR(VLOOKUP(I10,BaseDivisores[[Codigo]:[Preço]],3,0),"") | M10: =IFERROR((E10*K10*L10),"") | N10: =IFERROR(INDEX(BASE_VIDROS!$A:$A,MATCH(O10,BASE_VIDROS!$B:$B,0)),"") -> 003184 | O10: Refletivo Champanhe 4MM | P10: =IFERROR(VLOOKUP(N10,BaseVidros[[Codigo]:[Preço]],3,0),"") -> 179.26 | Q10: =IFERROR(E10*F10*P10,"") -> 117.25289 | R10: =E10*F10 -> 0.654094
A11: 57 | B11: =IFERROR(INDEX(PERFIl!$A:$A,MATCH(C11,PERFIl!$B:$B,0)),"") -> 17695 | C11: Perfil DES-1934 Anod (3025) | D11: =IFERROR(VLOOKUP(B11,PERFIl!$A:$C,3,0),"") -> 35.6 | E11: 0.502 | F11: 2.459 | G11: =((E11*2)+(F11*2)) -> 5.922 | H11: =IFERROR(((E11*2)+(F11*2))*(D11),"") -> 210.8232 | I11: =IFERROR(INDEX(DIVISORES!$A:$A,MATCH(J11,DIVISORES!$B:$B,0)),"") | K11: 1 | L11: =IFERROR(VLOOKUP(I11,BaseDivisores[[Codigo]:[Preço]],3,0),"") | M11: =IFERROR((E11*K11*L11),"") | N11: =IFERROR(INDEX(BASE_VIDROS!$A:$A,MATCH(O11,BASE_VIDROS!$B:$B,0)),"") -> 003183 | O11: Espelho Prata Cebrace | P11: =IFERROR(VLOOKUP(N11,BaseVidros[[Codigo]:[Preço]],3,0),"") -> 179.82 | Q11: =IFERROR(E11*F11*P11,"") -> 221.97304 | R11: =E11*F11 -> 1.234418
A12: 57 | B12: =IFERROR(INDEX(PERFIl!$A:$A,MATCH(C12,PERFIl!$B:$B,0)),"") | D12: =IFERROR(VLOOKUP(B12,PERFIl!$A:$C,3,0),"") | E12: 0 | F12: 0 | G12: =((E12*2)+(F12*2)) -> 0 | H12: =IFERROR(((E12*2)+(F12*2))*(D12),"") | I12: =IFERROR(INDEX(DIVISORES!$A:$A,MATCH(J12,DIVISORES!$B:$B,0)),"") | K12: 1 | L12: =IFERROR(VLOOKUP(I12,BaseDivisores[[Codigo]:[Preço]],3,0),"") | M12: =IFERROR((E12*K12*L12),"") | N12: =IFERROR(INDEX(BASE_VIDROS!$A:$A,MATCH(O12,BASE_VIDROS!$B:$B,0)),"") | P12: =IFERROR(VLOOKUP(N12,BaseVidros[[Codigo]:[Preço]],3,0),"") | Q12: =IFERROR(E12*F12*P12,"") | R12: =E12*F12 -> 0
A13: 57 | B13: =IFERROR(INDEX(PERFIl!$A:$A,MATCH(C13,PERFIl!$B:$B,0)),"") | D13: =IFERROR(VLOOKUP(B13,PERFIl!$A:$C,3,0),"") | E13: 0 | F13: 0 | G13: =((E13*2)+(F13*2)) -> 0 | H13: =IFERROR(((E13*2)+(F13*2))*(D13),"") | I13: =IFERROR(INDEX(DIVISORES!$A:$A,MATCH(J13,DIVISORES!$B:$B,0)),"") | K13: 1 | L13: =IFERROR(VLOOKUP(I13,BaseDivisores[[Codigo]:[Preço]],3,0),"") | M13: =IFERROR((E13*K13*L13),"") | N13: =IFERROR(INDEX(BASE_VIDROS!$A:$A,MATCH(O13,BASE_VIDROS!$B:$B,0)),"") | P13: =IFERROR(VLOOKUP(N13,BaseVidros[[Codigo]:[Preço]],3,0),"") | Q13: =IFERROR(E13*F13*P13,"") | R13: =E13*F13 -> 0
B15: Puxador | G15: Metros | H15: Película / Pintura / Serviços | L15: Portas Prontas | O15: Valor Total:
B16: Cód. | C16: Tamanho (m) | D16: Modelo | E16: R$ Lin. | F16: Total | G16: Qtde | H16: Cód | I16: Modelo | J16: R$ m² | K16: Total | L16: Qtd. | M16: Unitario | N16: Total
B17: =IFERROR(INDEX(PUXADOR!$A:$A,MATCH(D17,PUXADOR!$B:$B,0)),"") -> 014366 | C17: 1.814 | D17: Puxador 2019 Preto (2019) | E17: =IFERROR(VLOOKUP(B17,PUXADOR!$A:$C,3,0),"") -> 41.5 | F17: =IFERROR(C17*E17,"") -> 75.281 | G17: =C17 -> 1.814 | H17: =IFERROR(INDEX(BaseExtra[Código],MATCH(I17,BaseExtra[Item],0)),"") | J17: =IFERROR(VLOOKUP(H17,BaseExtra[],3,0),"") | K17: =IFERROR(E6*F6*J17,"") | L17: 0 | M17: =SUM(H6,M6,Q6,F17,K17,EXTRAS!$C$11) -> 393.361 | N17: =PRODUCT(L17,M17) -> 0 | O17: =SUM(N17:N24) -> 60
B18: =IFERROR(INDEX(PUXADOR!$A:$A,MATCH(D18,PUXADOR!$B:$B,0)),"") -> 002468 | C18: 0.15 | D18: Puxador DES-239 Anodizado (2010 - 20,5mm) | E18: =IFERROR(VLOOKUP(B18,PUXADOR!$A:$C,3,0),"") -> 25.6 | F18: =IFERROR(C18*E18,"") -> 3.84 | G18: =C18 -> 0.15 | H18: =IFERROR(INDEX(BaseExtra[Código],MATCH(I18,BaseExtra[Item],0)),"") | J18: =IFERROR(VLOOKUP(H18,BaseExtra[],3,0),"") | K18: =IFERROR(E7*F7*J18,"") | L18: 0 | M18: =SUM(H7,M7,Q7,F18,K18,EXTRAS!$C$11) -> 453.83835 | N18: =PRODUCT(L18,M18) -> 0
B19: =IFERROR(INDEX(PUXADOR!$A:$A,MATCH(D19,PUXADOR!$B:$B,0)),"") -> 007107 | C19: 1.23 | D19: Puxador DES-112 Anodizado (2015) | E19: =IFERROR(VLOOKUP(B19,PUXADOR!$A:$C,3,0),"") -> 30.1 | F19: =IFERROR(C19*E19,"") -> 37.023 | G19: =C19 -> 1.23 | H19: =IFERROR(INDEX(BaseExtra[Código],MATCH(I19,BaseExtra[Item],0)),"") | J19: =IFERROR(VLOOKUP(H19,BaseExtra[],3,0),"") | K19: =IFERROR(E8*F8*J19,"") | L19: 0 | M19: =SUM(H8,M8,Q8,F19,K19,EXTRAS!$C$11) -> 688.71777 | N19: =PRODUCT(L19,M19) -> 0
B20: =IFERROR(INDEX(PUXADOR!$A:$A,MATCH(D20,PUXADOR!$B:$B,0)),"") -> 007107 | C20: 1.23 | D20: Puxador DES-112 Anodizado (2015) | E20: =IFERROR(VLOOKUP(B20,PUXADOR!$A:$C,3,0),"") -> 30.1 | F20: =IFERROR(C20*E20,"") -> 37.023 | G20: =C20 -> 1.23 | H20: =IFERROR(INDEX(BaseExtra[Código],MATCH(I20,BaseExtra[Item],0)),"") | J20: =IFERROR(VLOOKUP(H20,BaseExtra[],3,0),"") | K20: =IFERROR(E9*F9*J20,"") | L20: 0 | M20: =SUM(H9,M9,Q9,F20,K20,EXTRAS!$C$11) -> 752.92197 | N20: =PRODUCT(L20,M20) -> 0
B21: =IFERROR(INDEX(PUXADOR!$A:$A,MATCH(D21,PUXADOR!$B:$B,0)),"") -> 007107 | C21: 1.23 | D21: Puxador DES-112 Anodizado (2015) | E21: =IFERROR(VLOOKUP(B21,PUXADOR!$A:$C,3,0),"") -> 30.1 | F21: =IFERROR(C21*E21,"") -> 37.023 | G21: =C21 -> 1.23 | H21: =IFERROR(INDEX(BaseExtra[Código],MATCH(I21,BaseExtra[Item],0)),"") | J21: =IFERROR(VLOOKUP(H21,BaseExtra[],3,0),"") | K21: =IFERROR(E10*F10*J21,"") | L21: 0 | M21: =SUM(H10,M10,Q10,F21,K21,EXTRAS!$C$11) -> 408.29589 | N21: =PRODUCT(L21,M21) -> 0
B22: =IFERROR(INDEX(PUXADOR!$A:$A,MATCH(D22,PUXADOR!$B:$B,0)),"") -> 007107 | C22: 1.25 | D22: Puxador DES-112 Anodizado (2015) | E22: =IFERROR(VLOOKUP(B22,PUXADOR!$A:$C,3,0),"") -> 30.1 | F22: =IFERROR(C22*E22,"") -> 37.625 | G22: =C22 -> 1.25 | H22: =IFERROR(INDEX(BaseExtra[Código],MATCH(I22,BaseExtra[Item],0)),"") -> 1 | I22: Branca Simples | J22: =IFERROR(VLOOKUP(H22,BaseExtra[],3,0),"") -> 25 | K22: =IFERROR(E11*F11*J22,"") -> 30.86045 | L22: 0 | M22: =SUM(H11,M11,Q11,F22,K22,EXTRAS!$C$11) -> 561.28169 | N22: =PRODUCT(L22,M22) -> 0
B23: =IFERROR(INDEX(PUXADOR!$A:$A,MATCH(D23,PUXADOR!$B:$B,0)),"") | E23: =IFERROR(VLOOKUP(B23,PUXADOR!$A:$C,3,0),"") | F23: =IFERROR(C23*E23,"") | G23: =C23 -> 0 | H23: =IFERROR(INDEX(BaseExtra[Código],MATCH(I23,BaseExtra[Item],0)),"") | J23: =IFERROR(VLOOKUP(H23,BaseExtra[],3,0),"") | K23: =IFERROR(E12*F12*J23,"") | L23: 0 | M23: =SUM(H12,M12,Q12,F23,K23,EXTRAS!$C$11) -> 60 | N23: =PRODUCT(L23,M23) -> 0
B24: =IFERROR(INDEX(PUXADOR!$A:$A,MATCH(D24,PUXADOR!$B:$B,0)),"") | E24: =IFERROR(VLOOKUP(B24,PUXADOR!$A:$C,3,0),"") | F24: =IFERROR(C24*E24,"") | G24: =C24 -> 0 | H24: =IFERROR(INDEX(BaseExtra[Código],MATCH(I24,BaseExtra[Item],0)),"") | J24: =IFERROR(VLOOKUP(H24,BaseExtra[],3,0),"") | K24: =IFERROR(E13*F13*J24,"") | M24: =SUM(H13,M13,Q13,F24,K24,EXTRAS!$C$11) -> 60 | N24: =PRODUCT(L24,M24) -> 60
B26: Extra

Sheet 1x Perfil Puxador
B3: Planilha de Cálculo para Portas de Alumínio (09/2023)
B4: Perfil | I4: Divisor | N4: Vidros
B5: Cód | C5: Modelo | D5: Valor | E5: Base (m) | F5: Altura (m) | G5: Qtde | H5: Total | I5: Cód. | J5: Modelo | K5: Qt | L5: R$ Lin. | M5: Total | N5: Cód | O5: Modelo | P5: R$ m² | Q5: Total | R5: M²
A6: 39 | B6: =IFERROR(INDEX(PERFIl!$A:$A,MATCH(C6,PERFIl!$B:$B,0)),"") -> 003525 | C6: Perfil DES-226 Anodizado (226) | D6: =IFERROR(VLOOKUP(B6,PERFIl!$A:$C,3,0),"") -> 61.7 | E6: 0.4 | F6: 2 | G6: =((E6*2)+(F6)) -> 2.8 | H6: =IFERROR(((E6*2)+(F6))*(D6),"") -> 172.76 | I6: =IFERROR(INDEX(DIVISORES!$A:$A,MATCH(J6,DIVISORES!$B:$B,0)),"") | K6: 2 | L6: =IFERROR(VLOOKUP(I6,BaseDivisores[[Codigo]:[Preço]],3,0),"") | M6: =IFERROR((E6*K6*L6),"") | N6: =IFERROR(INDEX(BASE_VIDROS!$A:$A,MATCH(O6,BASE_VIDROS!$B:$B,0)),"") -> 006250 | O6: Incolor 4MM | P6: =IFERROR(VLOOKUP(N6,BaseVidros[[Codigo]:[Preço]],3,0),"") -> 109 | Q6: =IFERROR(E6*F6*P6,"") -> 87.2 | R6: =E6*F6 -> 0.8
A7: 57 | B7: =IFERROR(INDEX(PERFIl!$A:$A,MATCH(C7,PERFIl!$B:$B,0)),"") -> 003525 | C7: Perfil DES-226 Anodizado (226) | D7: =IFERROR(VLOOKUP(B7,PERFIl!$A:$C,3,0),"") -> 61.7 | E7: 0.9 | F7: 0.56 | G7: =((E7*2)+(F7)) -> 2.36 | H7: =IFERROR(((E7*2)+(F7))*(D7),"") -> 145.612 | I7: =IFERROR(INDEX(DIVISORES!$A:$A,MATCH(J7,DIVISORES!$B:$B,0)),"") | K7: 1 | L7: =IFERROR(VLOOKUP(I7,BaseDivisores[[Codigo]:[Preço]],3,0),"") | M7: =IFERROR((E7*K7*L7),"") | N7: =IFERROR(INDEX(BASE_VIDROS!$A:$A,MATCH(O7,BASE_VIDROS!$B:$B,0)),"") | O7: Espelho Prata 4MM Opt Cebrace | P7: =IFERROR(VLOOKUP(N7,BaseVidros[[Codigo]:[Preço]],3,0),"") | Q7: =IFERROR(E7*F7*P7,"") | R7: =E7*F7 -> 0.504
A8: 57 | B8: =IFERROR(INDEX(PERFIl!$A:$A,MATCH(C8,PERFIl!$B:$B,0)),"") -> 011096 | C8: Perfil Di Base Anod (3579 Economico) Imp | D8: =IFERROR(VLOOKUP(B8,PERFIl!$A:$C,3,0),"") -> 44.25 | E8: 0.565 | F8: 2.36 | G8: =((E8*2)+(F8)) -> 3.49 | H8: =IFERROR(((E8*2)+(F8))*(D8),"") -> 154.4325 | I8: =IFERROR(INDEX(DIVISORES!$A:$A,MATCH(J8,DIVISORES!$B:$B,0)),"") | K8: 1 | L8: =IFERROR(VLOOKUP(I8,BaseDivisores[[Codigo]:[Preço]],3,0),"") | M8: =IFERROR((E8*K8*L8),"") | N8: =IFERROR(INDEX(BASE_VIDROS!$A:$A,MATCH(O8,BASE_VIDROS!$B:$B,0)),"") -> 003184 | O8: Refletivo Champanhe 4MM | P8: =IFERROR(VLOOKUP(N8,BaseVidros[[Codigo]:[Preço]],3,0),"") -> 179.26 | Q8: =IFERROR(E8*F8*P8,"") -> 239.02528 | R8: =E8*F8 -> 1.3334
A9: 57 | B9: =IFERROR(INDEX(PERFIl!$A:$A,MATCH(C9,PERFIl!$B:$B,0)),"") | D9: =IFERROR(VLOOKUP(B9,PERFIl!$A:$C,3,0),"") | G9: =((E9*2)+(F9)) -> 0 | H9: =IFERROR(((E9*2)+(F9))*(D9),"") | I9: =IFERROR(INDEX(DIVISORES!$A:$A,MATCH(J9,DIVISORES!$B:$B,0)),"") | K9: 1 | L9: =IFERROR(VLOOKUP(I9,BaseDivisores[[Codigo]:[Preço]],3,0),"") | M9: =IFERROR((E9*K9*L9),"") | N9: =IFERROR(INDEX(BASE_VIDROS!$A:$A,MATCH(O9,BASE_VIDROS!$B:$B,0)),"") | P9: =IFERROR(VLOOKUP(N9,BaseVidros[[Codigo]:[Preço]],3,0),"") | Q9: =IFERROR(E9*F9*P9,"") | R9: =E9*F9 -> 0
A10: 57 | B10: =IFERROR(INDEX(PERFIl!$A:$A,MATCH(C10,PERFIl!$B:$B,0)),"") | D10: =IFERROR(VLOOKUP(B10,PERFIl!$A:$C,3,0),"") | G10: =((E10*2)+(F10)) -> 0 | H10: =IFERROR(((E10*2)+(F10))*(D10),"") | I10: =IFERROR(INDEX(DIVISORES!$A:$A,MATCH(J10,DIVISORES!$B:$B,0)),"") | K10: 1 | L10: =IFERROR(VLOOKUP(I10,BaseDivisores[[Codigo]:[Preço]],3,0),"") | M10: =IFERROR((E10*K10*L10),"") | N10: =IFERROR(INDEX(BASE_VIDROS!$A:$A,MATCH(O10,BASE_VIDROS!$B:$B,0)),"") | P10: =IFERROR(VLOOKUP(N10,BaseVidros[[Codigo]:[Preço]],3,0),"") | Q10: =IFERROR(E10*F10*P10,"") | R10: =E10*F10 -> 0
A11: 57 | B11: =IFERROR(INDEX(PERFIl!$A:$A,MATCH(C11,PERFIl!$B:$B,0)),"") | D11: =IFERROR(VLOOKUP(B11,PERFIl!$A:$C,3,0),"") | G11: =((E11*2)+(F11)) -> 0 | H11: =IFERROR(((E11*2)+(F11))*(D11),"") | I11: =IFERROR(INDEX(DIVISORES!$A:$A,MATCH(J11,DIVISORES!$B:$B,0)),"") | K11: 1 | L11: =IFERROR(VLOOKUP(I11,BaseDivisores[[Codigo]:[Preço]],3,0),"") | M11: =IFERROR((E11*K11*L11),"") | N11: =IFERROR(INDEX(BASE_VIDROS!$A:$A,MATCH(O11,BASE_VIDROS!$B:$B,0)),"") | P11: =IFERROR(VLOOKUP(N11,BaseVidros[[Codigo]:[Preço]],3,0),"") | Q11: =IFERROR(E11*F11*P11,"") | R11: =E11*F11 -> 0
A12: 57 | B12: =IFERROR(INDEX(PERFIl!$A:$A,MATCH(C12,PERFIl!$B:$B,0)),"") | D12: =IFERROR(VLOOKUP(B12,PERFIl!$A:$C,3,0),"") | G12: =((E12*2)+(F12)) -> 0 | H12: =IFERROR(((E12*2)+(F12))*(D12),"") | I12: =IFERROR(INDEX(DIVISORES!$A:$A,MATCH(J12,DIVISORES!$B:$B,0)),"") | K12: 1 | L12: =IFERROR(VLOOKUP(I12,BaseDivisores[[Codigo]:[Preço]],3,0),"") | M12: =IFERROR((E12*K12*L12),"") | N12: =IFERROR(INDEX(BASE_VIDROS!$A:$A,MATCH(O12,BASE_VIDROS!$B:$B,0)),"") | P12: =IFERROR(VLOOKUP(N12,BaseVidros[[Codigo]:[Preço]],3,0),"") | Q12: =IFERROR(E12*F12*P12,"") | R12: =E12*F12 -> 0
A13: 57 | B13: =IFERROR(INDEX(PERFIl!$A:$A,MATCH(C13,PERFIl!$B:$B,0)),"") | D13: =IFERROR(VLOOKUP(B13,PERFIl!$A:$C,3,0),"") | G13: =((E13*2)+(F13)) -> 0 | H13: =IFERROR(((E13*2)+(F13))*(D13),"") | I13: =IFERROR(INDEX(DIVISORES!$A:$A,MATCH(J13,DIVISORES!$B:$B,0)),"") | K13: 1 | L13: =IFERROR(VLOOKUP(I13,BaseDivisores[[Codigo]:[Preço]],3,0),"") | M13: =IFERROR((E13*K13*L13),"") | N13: =IFERROR(INDEX(BASE_VIDROS!$A:$A,MATCH(O13,BASE_VIDROS!$B:$B,0)),"") | P13: =IFERROR(VLOOKUP(N13,BaseVidros[[Codigo]:[Preço]],3,0),"") | Q13: =IFERROR(E13*F13*P13,"") | R13: =E13*F13 -> 0
B15: Perfil_Puxador | G15: Metros | H15: Película / Pintura / Serviços | L15: Portas Prontas | O15: Valor Total:
B16: Cód. | C16: Tamanho (m) | D16: Modelo | E16: R$ Lin. | F16: Total | G16: Qtde | H16: Cód | I16: Modelo | J16: R$ m² | K16: Total | L16: Qtd. | M16: Unitario | N16: Total
B17: =IFERROR(INDEX(PERFIL_PUXADOR!$A:$A,MATCH(D17,PERFIL_PUXADOR!$B:$B,0)),"") -> 003747 | C17: =F6 -> 2 | D17: Perfil Puxador DES-227 Anodizado (227) | E17: =IFERROR(VLOOKUP(B17,PERFIL_PUXADOR!$A:$C,3,0),"") -> 72.15 | F17: =IFERROR(C17*E17,"") -> 144.3 | G17: =C17 -> 2 | H17: =IFERROR(INDEX(BaseExtra[Código],MATCH(I17,BaseExtra[Item],0)),"") | J17: =IFERROR(VLOOKUP(H17,BaseExtra[],3,0),"") | K17: =IFERROR(E6*F6*J17,"") | L17: 0 | M17: =SUM(H6,M6,Q6,F17,K17,EXTRAS!$C$11) -> 464.26 | N17: =PRODUCT(L17,M17) -> 0 | O17: =SUM(N17:N24) -> 0
B18: =IFERROR(INDEX(PERFIL_PUXADOR!$A:$A,MATCH(D18,PERFIL_PUXADOR!$B:$B,0)),"") -> 003526 | C18: =F7 -> 0.56 | D18: Perfil Puxador DES-950 Anodizado (950) | E18: =IFERROR(VLOOKUP(B18,PERFIL_PUXADOR!$A:$C,3,0),"") -> 83.69 | F18: =IFERROR(C18*E18,"") -> 46.8664 | G18: =C18 -> 0.56 | H18: =IFERROR(INDEX(BaseExtra[Código],MATCH(I18,BaseExtra[Item],0)),"") | J18: =IFERROR(VLOOKUP(H18,BaseExtra[],3,0),"") | K18: =IFERROR(E7*F7*J18,"") | L18: 0 | M18: =SUM(H7,M7,Q7,F18,K18,EXTRAS!$C$11) -> 252.4784 | N18: =PRODUCT(L18,M18) -> 0
B19: =IFERROR(INDEX(PERFIL_PUXADOR!$A:$A,MATCH(D19,PERFIL_PUXADOR!$B:$B,0)),"") -> 009951 | C19: =F8 -> 2.36 | D19: Perfil Puxador DES-204 Anodizado (204) | E19: =IFERROR(VLOOKUP(B19,PERFIL_PUXADOR!$A:$C,3,0),"") -> 79.45 | F19: =IFERROR(C19*E19,"") -> 187.502 | G19: =C19 -> 2.36 | H19: =IFERROR(INDEX(BaseExtra[Código],MATCH(I19,BaseExtra[Item],0)),"") | J19: =IFERROR(VLOOKUP(H19,BaseExtra[],3,0),"") | K19: =IFERROR(E8*F8*J19,"") | L19: 0 | M19: =SUM(H8,M8,Q8,F19,K19,EXTRAS!$C$11) -> 640.95978 | N19: =PRODUCT(L19,M19) -> 0
B20: =IFERROR(INDEX(PERFIL_PUXADOR!$A:$A,MATCH(D20,PERFIL_PUXADOR!$B:$B,0)),"") | C20: =F9 -> 0 | E20: =IFERROR(VLOOKUP(B20,PERFIL_PUXADOR!$A:$C,3,0),"") | F20: =IFERROR(C20*E20,"") | G20: =C20 -> 0 | H20: =IFERROR(INDEX(BaseExtra[Código],MATCH(I20,BaseExtra[Item],0)),"") | J20: =IFERROR(VLOOKUP(H20,BaseExtra[],3,0),"") | K20: =IFERROR(E9*F9*J20,"") | L20: 0 | M20: =SUM(H9,M9,Q9,F20,K20,EXTRAS!$C$11) -> 60 | N20: =PRODUCT(L20,M20) -> 0
B21: =IFERROR(INDEX(PERFIL_PUXADOR!$A:$A,MATCH(D21,PERFIL_PUXADOR!$B:$B,0)),"") | C21: =F10 -> 0 | E21: =IFERROR(VLOOKUP(B21,PERFIL_PUXADOR!$A:$C,3,0),"") | F21: =IFERROR(C21*E21,"") | G21: =C21 -> 0 | H21: =IFERROR(INDEX(BaseExtra[Código],MATCH(I21,BaseExtra[Item],0)),"") | J21: =IFERROR(VLOOKUP(H21,BaseExtra[],3,0),"") | K21: =IFERROR(E10*F10*J21,"") | L21: 0 | M21: =SUM(H10,M10,Q10,F21,K21,EXTRAS!$C$11) -> 60 | N21: =PRODUCT(L21,M21) -> 0
B22: =IFERROR(INDEX(PERFIL_PUXADOR!$A:$A,MATCH(D22,PERFIL_PUXADOR!$B:$B,0)),"") | C22: =F11 -> 0 | E22: =IFERROR(VLOOKUP(B22,PERFIL_PUXADOR!$A:$C,3,0),"") | F22: =IFERROR(C22*E22,"") | G22: =C22 -> 0 | H22: =IFERROR(INDEX(BaseExtra[Código],MATCH(I22,BaseExtra[Item],0)),"") | J22: =IFERROR(VLOOKUP(H22,BaseExtra[],3,0),"") | K22: =IFERROR(E11*F11*J22,"") | L22: 0 | M22: =SUM(H11,M11,Q11,F22,K22,EXTRAS!$C$11) -> 60 | N22: =PRODUCT(L22,M22) -> 0
B23: =IFERROR(INDEX(PERFIL_PUXADOR!$A:$A,MATCH(D23,PERFIL_PUXADOR!$B:$B,0)),"") | C23: =F12 -> 0 | E23: =IFERROR(VLOOKUP(B23,PERFIL_PUXADOR!$A:$C,3,0),"") | F23: =IFERROR(C23*E23,"") | G23: =C23 -> 0 | H23: =IFERROR(INDEX(BaseExtra[Código],MATCH(I23,BaseExtra[Item],0)),"") | J23: =IFERROR(VLOOKUP(H23,BaseExtra[],3,0),"") | K23: =IFERROR(E12*F12*J23,"") | L23: 0 | M23: =SUM(H12,M12,Q12,F23,K23,EXTRAS!$C$11) -> 60 | N23: =PRODUCT(L23,M23) -> 0
B24: =IFERROR(INDEX(PERFIL_PUXADOR!$A:$A,MATCH(D24,PERFIL_PUXADOR!$B:$B,0)),"") | C24: =F13 -> 0 | E24: =IFERROR(VLOOKUP(B24,PERFIL_PUXADOR!$A:$C,3,0),"") | F24: =IFERROR(C24*E24,"") | G24: =C24 -> 0 | H24: =IFERROR(INDEX(BaseExtra[Código],MATCH(I24,BaseExtra[Item],0)),"") | J24: =IFERROR(VLOOKUP(H24,BaseExtra[],3,0),"") | K24: =IFERROR(E13*F13*J24,"") | L24: 0 | M24: =SUM(H13,M13,Q13,F24,K24,EXTRAS!$C$11) -> 60 | N24: =PRODUCT(L24,M24) -> 0
B26: Extra

Sheet 2x Perfil Puxador
B3: Planilha de Cálculo para Portas de Alumínio (09/2023)
B4: Perfil | I4: Divisor | N4: Vidros
B5: Cód | C5: Modelo | D5: Valor | E5: Base (m) | F5: Altura (m) | G5: Qtde | H5: Total | I5: Cód. | J5: Modelo | K5: Qt | L5: R$ Lin. | M5: Total | N5: Cód | O5: Modelo | P5: R$ m² | Q5: Total | R5: M²
A6: 39 | B6: =IFERROR(INDEX(PERFIl!$A:$A,MATCH(C6,PERFIl!$B:$B,0)),"") -> 014259 | C6: Perfil 3136 Inox Escovado (3136) | D6: =IFERROR(VLOOKUP(B6,PERFIl!$A:$C,3,0),"") -> 72.5 | E6: 0.74 | F6: 2.408 | G6: =E6*2 -> 1.48 | H6: =IFERROR(G6*D6,"") -> 107.3 | I6: =IFERROR(INDEX(DIVISORES!$A:$A,MATCH(J6,DIVISORES!$B:$B,0)),"") | K6: 1 | L6: =IFERROR(VLOOKUP(I6,BaseDivisores[[Codigo]:[Preço]],3,0),"") | M6: =IFERROR((E6*K6*L6),"") | N6: =IFERROR(INDEX(BASE_VIDROS!$A:$A,MATCH(O6,BASE_VIDROS!$B:$B,0)),"") -> 003184 | O6: Refletivo Champanhe 4MM | P6: =IFERROR(VLOOKUP(N6,BaseVidros[[Codigo]:[Preço]],3,0),"") -> 179.26 | Q6: =IFERROR(E6*F6*P6,"") -> 319.42698 | R6: =E6*F6 -> 1.78192
A7: 57 | B7: =IFERROR(INDEX(PERFIl!$A:$A,MATCH(C7,PERFIl!$B:$B,0)),"") -> 011277 | C7: Perfil DES-198 Inox Escovado (3579) | D7: =IFERROR(VLOOKUP(B7,PERFIl!$A:$C,3,0),"") -> 63.7 | G7: =E7*2 -> 0 | H7: =IFERROR(G7*D7,"") -> 0 | I7: =IFERROR(INDEX(DIVISORES!$A:$A,MATCH(J7,DIVISORES!$B:$B,0)),"") | K7: 1 | L7: =IFERROR(VLOOKUP(I7,BaseDivisores[[Codigo]:[Preço]],3,0),"") | M7: =IFERROR((E7*K7*L7),"") | N7: =IFERROR(INDEX(BASE_VIDROS!$A:$A,MATCH(O7,BASE_VIDROS!$B:$B,0)),"") | O7: Espelho Prata 4MM Opt Cebrace | P7: =IFERROR(VLOOKUP(N7,BaseVidros[[Codigo]:[Preço]],3,0),"") | Q7: =IFERROR(E7*F7*P7,"") | R7: =E7*F7 -> 0
A8: 57 | B8: =IFERROR(INDEX(PERFIl!$A:$A,MATCH(C8,PERFIl!$B:$B,0)),"") -> 012119 | C8: Perfil DES-198 Preto (3579) | D8: =IFERROR(VLOOKUP(B8,PERFIl!$A:$C,3,0),"") -> 55.75 | G8: =E8*2 -> 0 | H8: =IFERROR(G8*D8,"") -> 0 | I8: =IFERROR(INDEX(DIVISORES!$A:$A,MATCH(J8,DIVISORES!$B:$B,0)),"") | K8: 1 | L8: =IFERROR(VLOOKUP(I8,BaseDivisores[[Codigo]:[Preço]],3,0),"") | M8: =IFERROR((E8*K8*L8),"") | N8: =IFERROR(INDEX(BASE_VIDROS!$A:$A,MATCH(O8,BASE_VIDROS!$B:$B,0)),"") | O8: Espelho Prata 4MM Opt Cebrace | P8: =IFERROR(VLOOKUP(N8,BaseVidros[[Codigo]:[Preço]],3,0),"") | Q8: =IFERROR(E8*F8*P8,"") | R8: =E8*F8 -> 0
A9: 57 | B9: =IFERROR(INDEX(PERFIl!$A:$A,MATCH(C9,PERFIl!$B:$B,0)),"") | D9: =IFERROR(VLOOKUP(B9,PERFIl!$A:$C,3,0),"") | G9: =E9*2 -> 0 | H9: =IFERROR(G9*D9,"") | I9: =IFERROR(INDEX(DIVISORES!$A:$A,MATCH(J9,DIVISORES!$B:$B,0)),"") | K9: 1 | L9: =IFERROR(VLOOKUP(I9,BaseDivisores[[Codigo]:[Preço]],3,0),"") | M9: =IFERROR((E9*K9*L9),"") | N9: =IFERROR(INDEX(BASE_VIDROS!$A:$A,MATCH(O9,BASE_VIDROS!$B:$B,0)),"") | P9: =IFERROR(VLOOKUP(N9,BaseVidros[[Codigo]:[Preço]],3,0),"") | Q9: =IFERROR(E9*F9*P9,"") | R9: =E9*F9 -> 0
A10: 57 | B10: =IFERROR(INDEX(PERFIl!$A:$A,MATCH(C10,PERFIl!$B:$B,0)),"") | D10: =IFERROR(VLOOKUP(B10,PERFIl!$A:$C,3,0),"") | G10: =E10*2 -> 0 | H10: =IFERROR(G10*D10,"") | I10: =IFERROR(INDEX(DIVISORES!$A:$A,MATCH(J10,DIVISORES!$B:$B,0)),"") | K10: 1 | L10: =IFERROR(VLOOKUP(I10,BaseDivisores[[Codigo]:[Preço]],3,0),"") | M10: =IFERROR((E10*K10*L10),"") | N10: =IFERROR(INDEX(BASE_VIDROS!$A:$A,MATCH(O10,BASE_VIDROS!$B:$B,0)),"") | P10: =IFERROR(VLOOKUP(N10,BaseVidros[[Codigo]:[Preço]],3,0),"") | Q10: =IFERROR(E10*F10*P10,"") | R10: =E10*F10 -> 0
A11: 57 | B11: =IFERROR(INDEX(PERFIl!$A:$A,MATCH(C11,PERFIl!$B:$B,0)),"") | D11: =IFERROR(VLOOKUP(B11,PERFIl!$A:$C,3,0),"") | G11: =E11*2 -> 0 | H11: =IFERROR(G11*D11,"") | I11: =IFERROR(INDEX(DIVISORES!$A:$A,MATCH(J11,DIVISORES!$B:$B,0)),"") | K11: 1 | L11: =IFERROR(VLOOKUP(I11,BaseDivisores[[Codigo]:[Preço]],3,0),"") | M11: =IFERROR((E11*K11*L11),"") | N11: =IFERROR(INDEX(BASE_VIDROS!$A:$A,MATCH(O11,BASE_VIDROS!$B:$B,0)),"") | P11: =IFERROR(VLOOKUP(N11,BaseVidros[[Codigo]:[Preço]],3,0),"") | Q11: =IFERROR(E11*F11*P11,"") | R11: =E11*F11 -> 0
A12: 57 | B12: =IFERROR(INDEX(PERFIl!$A:$A,MATCH(C12,PERFIl!$B:$B,0)),"") | D12: =IFERROR(VLOOKUP(B12,PERFIl!$A:$C,3,0),"") | G12: =E12*2 -> 0 | H12: =IFERROR(G12*D12,"") | I12: =IFERROR(INDEX(DIVISORES!$A:$A,MATCH(J12,DIVISORES!$B:$B,0)),"") | K12: 1 | L12: =IFERROR(VLOOKUP(I12,BaseDivisores[[Codigo]:[Preço]],3,0),"") | M12: =IFERROR((E12*K12*L12),"") | N12: =IFERROR(INDEX(BASE_VIDROS!$A:$A,MATCH(O12,BASE_VIDROS!$B:$B,0)),"") | P12: =IFERROR(VLOOKUP(N12,BaseVidros[[Codigo]:[Preço]],3,0),"") | Q12: =IFERROR(E12*F12*P12,"") | R12: =E12*F12 -> 0
A13: 57 | B13: =IFERROR(INDEX(PERFIl!$A:$A,MATCH(C13,PERFIl!$B:$B,0)),"") | D13: =IFERROR(VLOOKUP(B13,PERFIl!$A:$C,3,0),"") | G13: =E13*2 -> 0 | H13: =IFERROR(G13*D13,"") | I13: =IFERROR(INDEX(DIVISORES!$A:$A,MATCH(J13,DIVISORES!$B:$B,0)),"") | K13: 1 | L13: =IFERROR(VLOOKUP(I13,BaseDivisores[[Codigo]:[Preço]],3,0),"") | M13: =IFERROR((E13*K13*L13),"") | N13: =IFERROR(INDEX(BASE_VIDROS!$A:$A,MATCH(O13,BASE_VIDROS!$B:$B,0)),"") | P13: =IFERROR(VLOOKUP(N13,BaseVidros[[Codigo]:[Preço]],3,0),"") | Q13: =IFERROR(E13*F13*P13,"") | R13: =E13*F13 -> 0
B15: Perfil_Puxador | G15: Metros | H15: Película / Pintura / Serviços | L15: Portas Prontas | O15: Valor Total:
B16: Cód. | C16: Tamanho (m) | D16: Modelo | E16: R$ Lin. | F16: Total | G16: Qtde | H16: Cód | I16: Modelo | J16: R$ m² | K16: Total | L16: Qtd. | M16: Unitario | N16: Total
B17: =IFERROR(INDEX(PERFIL_PUXADOR!$A:$A,MATCH(D17,PERFIL_PUXADOR!$B:$B,0)),"") -> 2189 | C17: =2*F6 -> 4.816 | D17: Perfil Pux 3366 Escovado | E17: =IFERROR(VLOOKUP(B17,PERFIL_PUXADOR!$A:$C,3,0),"") -> 104.9 | F17: =IFERROR(C17*E17,"") -> 505.1984 | G17: =C17 -> 4.816 | H17: =IFERROR(INDEX(BaseExtra[Código],MATCH(I17,BaseExtra[Item],0)),"") | J17: =IFERROR(VLOOKUP(H17,BaseExtra[],3,0),"") | K17: =IFERROR(E6*F6*J17,"") | L17: 0 | M17: =SUM(H6,M6,Q6,F17,K17,EXTRAS!$C$11) -> 991.92538 | N17: =PRODUCT(L17,M17) -> 0 | O17: =SUM(N17:N24) -> 0
B18: =IFERROR(INDEX(PERFIL_PUXADOR!$A:$A,MATCH(D18,PERFIL_PUXADOR!$B:$B,0)),"") -> 006082 | C18: =2*F7 -> 0 | D18: Perfil Puxador DES-950 Inox Escovado (950) | E18: =IFERROR(VLOOKUP(B18,PERFIL_PUXADOR!$A:$C,3,0),"") -> 106.5 | F18: =IFERROR(C18*E18,"") -> 0 | G18: =C18 -> 0 | H18: =IFERROR(INDEX(BaseExtra[Código],MATCH(I18,BaseExtra[Item],0)),"") -> 1 | I18: Branca Simples | J18: =IFERROR(VLOOKUP(H18,BaseExtra[],3,0),"") -> 25 | K18: =IFERROR(E7*F7*J18,"") -> 0 | L18: 0 | M18: =SUM(H7,M7,Q7,F18,K18,EXTRAS!$C$11) -> 60 | N18: =PRODUCT(L18,M18) -> 0
B19: =IFERROR(INDEX(PERFIL_PUXADOR!$A:$A,MATCH(D19,PERFIL_PUXADOR!$B:$B,0)),"") -> 012035 | C19: =2*F8 -> 0 | D19: Perfil Puxador DES-950 Preto Fosco (950) | E19: =IFERROR(VLOOKUP(B19,PERFIL_PUXADOR!$A:$C,3,0),"") -> 93.24 | F19: =IFERROR(C19*E19,"") -> 0 | G19: =C19 -> 0 | H19: =IFERROR(INDEX(BaseExtra[Código],MATCH(I19,BaseExtra[Item],0)),"") -> 1 | I19: Branca Simples | J19: =IFERROR(VLOOKUP(H19,BaseExtra[],3,0),"") -> 25 | K19: =IFERROR(E8*F8*J19,"") -> 0 | L19: 0 | M19: =SUM(H8,M8,Q8,F19,K19,EXTRAS!$C$11) -> 60 | N19: =PRODUCT(L19,M19) -> 0
B20: =IFERROR(INDEX(PERFIL_PUXADOR!$A:$A,MATCH(D20,PERFIL_PUXADOR!$B:$B,0)),"") | C20: =2*F9 -> 0 | E20: =IFERROR(VLOOKUP(B20,PERFIL_PUXADOR!$A:$C,3,0),"") | F20: =IFERROR(C20*E20,"") | G20: =C20 -> 0 | H20: =IFERROR(INDEX(BaseExtra[Código],MATCH(I20,BaseExtra[Item],0)),"") | J20: =IFERROR(VLOOKUP(H20,BaseExtra[],3,0),"") | K20: =IFERROR(E9*F9*J20,"") | L20: 0 | M20: =SUM(H9,M9,Q9,F20,K20,EXTRAS!$C$11) -> 60 | N20: =PRODUCT(L20,M20) -> 0
B21: =IFERROR(INDEX(PERFIL_PUXADOR!$A:$A,MATCH(D21,PERFIL_PUXADOR!$B:$B,0)),"") | C21: =2*F10 -> 0 | E21: =IFERROR(VLOOKUP(B21,PERFIL_PUXADOR!$A:$C,3,0),"") | F21: =IFERROR(C21*E21,"") | G21: =C21 -> 0 | H21: =IFERROR(INDEX(BaseExtra[Código],MATCH(I21,BaseExtra[Item],0)),"") | J21: =IFERROR(VLOOKUP(H21,BaseExtra[],3,0),"") | K21: =IFERROR(E10*F10*J21,"") | L21: 0 | M21: =SUM(H10,M10,Q10,F21,K21,EXTRAS!$C$11) -> 60 | N21: =PRODUCT(L21,M21) -> 0
B22: =IFERROR(INDEX(PERFIL_PUXADOR!$A:$A,MATCH(D22,PERFIL_PUXADOR!$B:$B,0)),"") | C22: =2*F11 -> 0 | E22: =IFERROR(VLOOKUP(B22,PERFIL_PUXADOR!$A:$C,3,0),"") | F22: =IFERROR(C22*E22,"") | G22: =C22 -> 0 | H22: =IFERROR(INDEX(BaseExtra[Código],MATCH(I22,BaseExtra[Item],0)),"") | J22: =IFERROR(VLOOKUP(H22,BaseExtra[],3,0),"") | K22: =IFERROR(E11*F11*J22,"") | L22: 0 | M22: =SUM(H11,M11,Q11,F22,K22,EXTRAS!$C$11) -> 60 | N22: =PRODUCT(L22,M22) -> 0
B23: =IFERROR(INDEX(PERFIL_PUXADOR!$A:$A,MATCH(D23,PERFIL_PUXADOR!$B:$B,0)),"") | C23: =2*F12 -> 0 | E23: =IFERROR(VLOOKUP(B23,PERFIL_PUXADOR!$A:$C,3,0),"") | F23: =IFERROR(C23*E23,"") | G23: =C23 -> 0 | H23: =IFERROR(INDEX(BaseExtra[Código],MATCH(I23,BaseExtra[Item],0)),"") | J23: =IFERROR(VLOOKUP(H23,BaseExtra[],3,0),"") | K23: =IFERROR(E12*F12*J23,"") | L23: 0 | M23: =SUM(H12,M12,Q12,F23,K23,EXTRAS!$C$11) -> 60 | N23: =PRODUCT(L23,M23) -> 0
B24: =IFERROR(INDEX(PERFIL_PUXADOR!$A:$A,MATCH(D24,PERFIL_PUXADOR!$B:$B,0)),"") | C24: =2*F13 -> 0 | E24: =IFERROR(VLOOKUP(B24,PERFIL_PUXADOR!$A:$C,3,0),"") | F24: =IFERROR(C24*E24,"") | G24: =C24 -> 0 | H24: =IFERROR(INDEX(BaseExtra[Código],MATCH(I24,BaseExtra[Item],0)),"") | J24: =IFERROR(VLOOKUP(H24,BaseExtra[],3,0),"") | K24: =IFERROR(E13*F13*J24,"") | L24: 0 | M24: =SUM(H13,M13,Q13,F24,K24,EXTRAS!$C$11) -> 60 | N24: =PRODUCT(L24,M24) -> 0
B26: Extra

Sheet Linha 1000
B2: Planilha de Cálculo para Portas de Alumínio (09/2023)
B3: Perfil Superior | I3: Perfil Inferior | M3: Vidros | S3: Vidros
B4: Cód | C4: Modelo | D4: R$ Lin. | E4: Largura SEM Pux (m) | F4: Altura COM Pux (m) | G4: Qtde | H4: Total | I4: Cód. | J4: Modelo | K4: R$ Lin. | L4: Total | M4: Qtd. M2 | N4: Cód | O4: Modelo | P4: R$ m² | Q4: Total | S4: Qtd. M2 | T4: Cód | U4: Modelo | V4: R$ m² | W4: Total
A5: 57 | B5: =IFERROR(INDEX(DIVISORIA_DE_AMBIENTE!$A:$A,MATCH(C5,DIVISORIA_DE_AMBIENTE!$B:$B,0)),"") -> 011406 | C5: Perfil RM-069 Preto (Travessa Superior) | D5: =IFERROR(VLOOKUP(B5,DIVISORIA_DE_AMBIENTE!$A:$C,3,0),"") -> 113.7 | E5: 0.81 | F5: 2.325 | G5: =(E5)*L16 -> 0 | H5: =IFERROR((SUM(E5+E5)*D5),"") -> 184.194 | I5: =IFERROR(INDEX(DIVISORIA_DE_AMBIENTE!$A:$A,MATCH(J5,DIVISORIA_DE_AMBIENTE!$B:$B,0)),"") -> 011407 | J5: Perfil RM-066 Preto (Travessa) | K5: =IFERROR(VLOOKUP(I5,DIVISORIA_DE_AMBIENTE!$A:$C,3,0),"") -> 62 | L5: =IFERROR((E5*K5),"") -> 50.22 | M5: =E5*F5 -> 1.88325 | N5: =IFERROR(INDEX(BASE_VIDROS!$A:$A,MATCH(O5,BASE_VIDROS!$B:$B,0)),"") | O5: Espelho Prata 4MM Opt Cebrace | P5: =IFERROR(VLOOKUP(N5,BaseVidros[[Codigo]:[Preço]],3,0),"") | Q5: =IFERROR(M5*P5,"") | S5: =E5*F5 -> 1.88325 | T5: =IFERROR(INDEX(BASE_VIDROS!$A:$A,MATCH(U5,BASE_VIDROS!$B:$B,0)),"") | U5: Espelho Prata 4MM Opt Cebrace | V5: =IFERROR(VLOOKUP(T5,BaseVidros[[Codigo]:[Preço]],3,0),"") | W5: =IFERROR(S5*V5,"") | Y5: 18
A6: 57 | B6: =IFERROR(INDEX(DIVISORIA_DE_AMBIENTE!$A:$A,MATCH(C6,DIVISORIA_DE_AMBIENTE!$B:$B,0)),"") | D6: =IFERROR(VLOOKUP(B6,DIVISORIA_DE_AMBIENTE!$A:$C,3,0),"") | E6: 0 | F6: 0 | G6: =(E6)*L17 -> 0 | H6: =IFERROR((SUM(E6+E6)*D6),"") | I6: =IFERROR(INDEX(DIVISORIA_DE_AMBIENTE!$A:$A,MATCH(J6,DIVISORIA_DE_AMBIENTE!$B:$B,0)),"") | K6: =IFERROR(VLOOKUP(I6,DIVISORIA_DE_AMBIENTE!$A:$C,3,0),"") | L6: =IFERROR((E6*K6),"") | M6: =E6*F6 -> 0 | N6: =IFERROR(INDEX(BASE_VIDROS!$A:$A,MATCH(O6,BASE_VIDROS!$B:$B,0)),"") | P6: =IFERROR(VLOOKUP(N6,BaseVidros[[Codigo]:[Preço]],3,0),"") | Q6: =IFERROR(M6*P6,"") | S6: =E6*F6 -> 0 | T6: =IFERROR(INDEX(BASE_VIDROS!$A:$A,MATCH(U6,BASE_VIDROS!$B:$B,0)),"") | V6: =IFERROR(VLOOKUP(T6,BaseVidros[[Codigo]:[Preço]],3,0),"") | W6: =IFERROR(S6*V6,"") | Y6: 18
A7: 57 | B7: =IFERROR(INDEX(DIVISORIA_DE_AMBIENTE!$A:$A,MATCH(C7,DIVISORIA_DE_AMBIENTE!$B:$B,0)),"") | D7: =IFERROR(VLOOKUP(B7,DIVISORIA_DE_AMBIENTE!$A:$C,3,0),"") | E7: 0 | F7: 0 | G7: =(E7)*L18 -> 0 | H7: =IFERROR((SUM(E7+E7)*D7),"") | I7: =IFERROR(INDEX(DIVISORIA_DE_AMBIENTE!$A:$A,MATCH(J7,DIVISORIA_DE_AMBIENTE!$B:$B,0)),"") | K7: =IFERROR(VLOOKUP(I7,DIVISORIA_DE_AMBIENTE!$A:$C,3,0),"") | L7: =IFERROR((E7*K7),"") | M7: =E7*F7 -> 0 | N7: =IFERROR(INDEX(BASE_VIDROS!$A:$A,MATCH(O7,BASE_VIDROS!$B:$B,0)),"") | P7: =IFERROR(VLOOKUP(N7,BaseVidros[[Codigo]:[Preço]],3,0),"") | Q7: =IFERROR(M7*P7,"") | S7: =E7*F7 -> 0 | T7: =IFERROR(INDEX(BASE_VIDROS!$A:$A,MATCH(U7,BASE_VIDROS!$B:$B,0)),"") | V7: =IFERROR(VLOOKUP(T7,BaseVidros[[Codigo]:[Preço]],3,0),"") | W7: =IFERROR(S7*V7,"") | Y7: 18
A8: 57 | B8: =IFERROR(INDEX(DIVISORIA_DE_AMBIENTE!$A:$A,MATCH(C8,DIVISORIA_DE_AMBIENTE!$B:$B,0)),"") | D8: =IFERROR(VLOOKUP(B8,DIVISORIA_DE_AMBIENTE!$A:$C,3,0),"") | E8: 0 | F8: 0 | G8: =(E8)*L19 -> 0 | H8: =IFERROR((SUM(E8+E8)*D8),"") | I8: =IFERROR(INDEX(DIVISORIA_DE_AMBIENTE!$A:$A,MATCH(J8,DIVISORIA_DE_AMBIENTE!$B:$B,0)),"") | K8: =IFERROR(VLOOKUP(I8,DIVISORIA_DE_AMBIENTE!$A:$C,3,0),"") | L8: =IFERROR((E8*K8),"") | M8: =E8*F8 -> 0 | N8: =IFERROR(INDEX(BASE_VIDROS!$A:$A,MATCH(O8,BASE_VIDROS!$B:$B,0)),"") | P8: =IFERROR(VLOOKUP(N8,BaseVidros[[Codigo]:[Preço]],3,0),"") | Q8: =IFERROR(M8*P8,"") | S8: =E8*F8 -> 0 | T8: =IFERROR(INDEX(BASE_VIDROS!$A:$A,MATCH(U8,BASE_VIDROS!$B:$B,0)),"") | V8: =IFERROR(VLOOKUP(T8,BaseVidros[[Codigo]:[Preço]],3,0),"") | W8: =IFERROR(S8*V8,"") | Y8: 18
A9: 57 | B9: =IFERROR(INDEX(DIVISORIA_DE_AMBIENTE!$A:$A,MATCH(C9,DIVISORIA_DE_AMBIENTE!$B:$B,0)),"") | D9: =IFERROR(VLOOKUP(B9,DIVISORIA_DE_AMBIENTE!$A:$C,3,0),"") | E9: 0 | F9: 0 | G9: =(E9)*L20 -> 0 | H9: =IFERROR((SUM(E9+E9)*D9),"") | I9: =IFERROR(INDEX(DIVISORIA_DE_AMBIENTE!$A:$A,MATCH(J9,DIVISORIA_DE_AMBIENTE!$B:$B,0)),"") | K9: =IFERROR(VLOOKUP(I9,DIVISORIA_DE_AMBIENTE!$A:$C,3,0),"") | L9: =IFERROR((E9*K9),"") | M9: =E9*F9 -> 0 | N9: =IFERROR(INDEX(BASE_VIDROS!$A:$A,MATCH(O9,BASE_VIDROS!$B:$B,0)),"") | P9: =IFERROR(VLOOKUP(N9,BaseVidros[[Codigo]:[Preço]],3,0),"") | Q9: =IFERROR(M9*P9,"") | S9: =E9*F9 -> 0 | T9: =IFERROR(INDEX(BASE_VIDROS!$A:$A,MATCH(U9,BASE_VIDROS!$B:$B,0)),"") | V9: =IFERROR(VLOOKUP(T9,BaseVidros[[Codigo]:[Preço]],3,0),"") | W9: =IFERROR(S9*V9,"") | Y9: 18
A10: 57 | B10: =IFERROR(INDEX(DIVISORIA_DE_AMBIENTE!$A:$A,MATCH(C10,DIVISORIA_DE_AMBIENTE!$B:$B,0)),"") | D10: =IFERROR(VLOOKUP(B10,DIVISORIA_DE_AMBIENTE!$A:$C,3,0),"") | E10: 0 | F10: 0 | G10: =(E10)*L21 -> 0 | H10: =IFERROR((SUM(E10+E10)*D10),"") | I10: =IFERROR(INDEX(DIVISORIA_DE_AMBIENTE!$A:$A,MATCH(J10,DIVISORIA_DE_AMBIENTE!$B:$B,0)),"") | K10: =IFERROR(VLOOKUP(I10,DIVISORIA_DE_AMBIENTE!$A:$C,3,0),"") | L10: =IFERROR((E10*K10),"") | M10: =E10*F10 -> 0 | N10: =IFERROR(INDEX(BASE_VIDROS!$A:$A,MATCH(O10,BASE_VIDROS!$B:$B,0)),"") | P10: =IFERROR(VLOOKUP(N10,BaseVidros[[Codigo]:[Preço]],3,0),"") | Q10: =IFERROR(M10*P10,"") | S10: =E10*F10 -> 0 | T10: =IFERROR(INDEX(BASE_VIDROS!$A:$A,MATCH(U10,BASE_VIDROS!$B:$B,0)),"") | V10: =IFERROR(VLOOKUP(T10,BaseVidros[[Codigo]:[Preço]],3,0),"") | W10: =IFERROR(S10*V10,"") | Y10: 18
A11: 57 | B11: =IFERROR(INDEX(DIVISORIA_DE_AMBIENTE!$A:$A,MATCH(C11,DIVISORIA_DE_AMBIENTE!$B:$B,0)),"") | D11: =IFERROR(VLOOKUP(B11,DIVISORIA_DE_AMBIENTE!$A:$C,3,0),"") | E11: 0 | F11: 0 | G11: =(E11)*L22 -> 0 | H11: =IFERROR((SUM(E11+E11)*D11),"") | I11: =IFERROR(INDEX(DIVISORIA_DE_AMBIENTE!$A:$A,MATCH(J11,DIVISORIA_DE_AMBIENTE!$B:$B,0)),"") | K11: =IFERROR(VLOOKUP(I11,DIVISORIA_DE_AMBIENTE!$A:$C,3,0),"") | L11: =IFERROR((E11*K11),"") | M11: =E11*F11 -> 0 | N11: =IFERROR(INDEX(BASE_VIDROS!$A:$A,MATCH(O11,BASE_VIDROS!$B:$B,0)),"") | P11: =IFERROR(VLOOKUP(N11,BaseVidros[[Codigo]:[Preço]],3,0),"") | Q11: =IFERROR(M11*P11,"") | S11: =E11*F11 -> 0 | T11: =IFERROR(INDEX(BASE_VIDROS!$A:$A,MATCH(U11,BASE_VIDROS!$B:$B,0)),"") | V11: =IFERROR(VLOOKUP(T11,BaseVidros[[Codigo]:[Preço]],3,0),"") | W11: =IFERROR(S11*V11,"") | Y11: 18
A12: 57 | B12: =IFERROR(INDEX(DIVISORIA_DE_AMBIENTE!$A:$A,MATCH(C12,DIVISORIA_DE_AMBIENTE!$B:$B,0)),"") | D12: =IFERROR(VLOOKUP(B12,DIVISORIA_DE_AMBIENTE!$A:$C,3,0),"") | E12: 0 | F12: 0 | G12: =(E12)*L23 -> 0 | H12: =IFERROR((SUM(E12+E12)*D12),"") | I12: =IFERROR(INDEX(DIVISORIA_DE_AMBIENTE!$A:$A,MATCH(J12,DIVISORIA_DE_AMBIENTE!$B:$B,0)),"") | K12: =IFERROR(VLOOKUP(I12,DIVISORIA_DE_AMBIENTE!$A:$C,3,0),"") | L12: =IFERROR((E12*K12),"") | M12: =E12*F12 -> 0 | N12: =IFERROR(INDEX(BASE_VIDROS!$A:$A,MATCH(O12,BASE_VIDROS!$B:$B,0)),"") | P12: =IFERROR(VLOOKUP(N12,BaseVidros[[Codigo]:[Preço]],3,0),"") | Q12: =IFERROR(M12*P12,"") | S12: =E12*F12 -> 0 | T12: =IFERROR(INDEX(BASE_VIDROS!$A:$A,MATCH(U12,BASE_VIDROS!$B:$B,0)),"") | V12: =IFERROR(VLOOKUP(T12,BaseVidros[[Codigo]:[Preço]],3,0),"") | W12: =IFERROR(S12*V12,"") | Y12: 18
B14: Puxador | H14: Película / Pintura / Serviços | L14: Portas Prontas | O14: Valor Total:
B15: Cód | C15: Modelo | D15: R$ Lin. | F15: Total | G15: Qtde | H15: Cód | I15: Modelo | J15: R$ m² | K15: Total | L15: Qtd. | M15: Unitario | N15: Total
B16: =IFERROR(INDEX(DIVISORIA_DE_AMBIENTE!$A:$A,MATCH(C16,DIVISORIA_DE_AMBIENTE!$B:$B,0)),"") -> 011405 | C16: Perfil Puxador RM-070 Preto | D16: =IFERROR(VLOOKUP(B16,DIVISORIA_DE_AMBIENTE!$A:$C,3,0),"") -> 96.3 | F16: =IFERROR((2*F5*D16),"") -> 447.795 | G16: =F5*2 -> 4.65 | H16: =IFERROR(INDEX(BaseExtra[Código],MATCH(I16,BaseExtra[Item],0)),"") -> 1 | I16: Branca Simples | J16: =IFERROR(VLOOKUP(H16,BaseExtra[],3,0),"") -> 25 | K16: =IFERROR(E5*F5*J16,"") -> 47.08125 | L16: 0 | M16: =SUM(H5,M5,Q5,F16,K16,EXTRAS!$C$11) -> 740.9535 | N16: =PRODUCT(L16,M16) -> 0 | O16: =SUM(N16:N23) -> 0
B17: =IFERROR(INDEX(DIVISORIA_DE_AMBIENTE!$A:$A,MATCH(C17,DIVISORIA_DE_AMBIENTE!$B:$B,0)),"") | D17: =IFERROR(VLOOKUP(B17,DIVISORIA_DE_AMBIENTE!$A:$C,3,0),"") | F17: =IFERROR((2*F6*D17),"") | G17: =F6*2 -> 0 | H17: =IFERROR(INDEX(#REF!,MATCH(I17,#REF!,0)),"") | J17: =IFERROR(VLOOKUP(H17,#REF!,3,0),"") | K17: =IFERROR(E6*F6*J17,"") | L17: 0 | M17: =SUM(H6,M6,Q6,F17,K17,EXTRAS!$C$11) -> 60 | N17: =PRODUCT(L17,M17) -> 0
B18: =IFERROR(INDEX(DIVISORIA_DE_AMBIENTE!$A:$A,MATCH(C18,DIVISORIA_DE_AMBIENTE!$B:$B,0)),"") | D18: =IFERROR(VLOOKUP(B18,DIVISORIA_DE_AMBIENTE!$A:$C,3,0),"") | F18: =IFERROR((2*F7*D18),"") | G18: =F7*2 -> 0 | H18: =IFERROR(INDEX(#REF!,MATCH(I18,#REF!,0)),"") | J18: =IFERROR(VLOOKUP(H18,#REF!,3,0),"") | K18: =IFERROR(E7*F7*J18,"") | L18: 0 | M18: =SUM(H7,M7,Q7,F18,K18,EXTRAS!$C$11) -> 60 | N18: =PRODUCT(L18,M18) -> 0
B19: =IFERROR(INDEX(DIVISORIA_DE_AMBIENTE!$A:$A,MATCH(C19,DIVISORIA_DE_AMBIENTE!$B:$B,0)),"") | D19: =IFERROR(VLOOKUP(B19,DIVISORIA_DE_AMBIENTE!$A:$C,3,0),"") | F19: =IFERROR((2*F8*D19),"") | G19: =F8*2 -> 0 | H19: =IFERROR(INDEX(#REF!,MATCH(I19,#REF!,0)),"") | J19: =IFERROR(VLOOKUP(H19,#REF!,3,0),"") | K19: =IFERROR(E8*F8*J19,"") | L19: 0 | M19: =SUM(H8,M8,Q8,F19,K19,EXTRAS!$C$11) -> 60 | N19: =PRODUCT(L19,M19) -> 0
B20: =IFERROR(INDEX(DIVISORIA_DE_AMBIENTE!$A:$A,MATCH(C20,DIVISORIA_DE_AMBIENTE!$B:$B,0)),"") | D20: =IFERROR(VLOOKUP(B20,DIVISORIA_DE_AMBIENTE!$A:$C,3,0),"") | F20: =IFERROR((2*F9*D20),"") | G20: =F9*2 -> 0 | H20: =IFERROR(INDEX(#REF!,MATCH(I20,#REF!,0)),"") | J20: =IFERROR(VLOOKUP(H20,#REF!,3,0),"") | K20: =IFERROR(E9*F9*J20,"") | L20: 0 | M20: =SUM(H9,M9,Q9,F20,K20,EXTRAS!$C$11) -> 60 | N20: =PRODUCT(L20,M20) -> 0
B21: =IFERROR(INDEX(DIVISORIA_DE_AMBIENTE!$A:$A,MATCH(C21,DIVISORIA_DE_AMBIENTE!$B:$B,0)),"") | D21: =IFERROR(VLOOKUP(B21,DIVISORIA_DE_AMBIENTE!$A:$C,3,0),"") | F21: =IFERROR((2*F10*D21),"") | G21: =F10*2 -> 0 | H21: =IFERROR(INDEX(#REF!,MATCH(I21,#REF!,0)),"") | J21: =IFERROR(VLOOKUP(H21,#REF!,3,0),"") | K21: =IFERROR(E10*F10*J21,"") | L21: 0 | M21: =SUM(H10,M10,Q10,F21,K21,EXTRAS!$C$11) -> 60 | N21: =PRODUCT(L21,M21) -> 0
B22: =IFERROR(INDEX(DIVISORIA_DE_AMBIENTE!$A:$A,MATCH(C22,DIVISORIA_DE_AMBIENTE!$B:$B,0)),"") | D22: =IFERROR(VLOOKUP(B22,DIVISORIA_DE_AMBIENTE!$A:$C,3,0),"") | F22: =IFERROR((2*F11*D22),"") | G22: =F11*2 -> 0 | H22: =IFERROR(INDEX(#REF!,MATCH(I22,#REF!,0)),"") | J22: =IFERROR(VLOOKUP(H22,#REF!,3,0),"") | K22: =IFERROR(E11*F11*J22,"") | L22: 0 | M22: =SUM(H11,M11,Q11,F22,K22,EXTRAS!$C$11) -> 60 | N22: =PRODUCT(L22,M22) -> 0
B23: =IFERROR(INDEX(DIVISORIA_DE_AMBIENTE!$A:$A,MATCH(C23,DIVISORIA_DE_AMBIENTE!$B:$B,0)),"") | D23: =IFERROR(VLOOKUP(B23,DIVISORIA_DE_AMBIENTE!$A:$C,3,0),"") | F23: =IFERROR((2*F12*D23),"") | G23: =F12*2 -> 0 | H23: =IFERROR(INDEX(#REF!,MATCH(I23,#REF!,0)),"") | J23: =IFERROR(VLOOKUP(H23,#REF!,3,0),"") | K23: =IFERROR(E12*F12*J23,"") | L23: 0 | M23: =SUM(H12,M12,Q12,F23,K23,EXTRAS!$C$11) -> 60 | N23: =PRODUCT(L23,M23) -> 0
B24: Extra

Sheet Vidros
B1: Planilha de Cálculo para Portas de Alumínio (09/2023)
B2: Tamanho das Peças | E2: Vidros | J2: Película / Pintura / Serviços | N2: Vidros Prontas | P2: Valor Total:
B3: Qtd. | C3: Base (m) | D3: Altura (m) | E3: Cód | F3: Modelo | G3: R$ m² | H3: Total | I3: M² | J3: Cód | K3: Modelo | L3: R$ m² | M3: Total | N3: Unitario | O3: Total
B4: 1 | C4: 1.101 | D4: 0.705 | E4: =IFERROR(INDEX(BaseVidros[Codigo],MATCH(F4,BaseVidros[Descrição],0)),"") -> 004101 | F4: Extra Branco 4MM | G4: =IFERROR(VLOOKUP(E4,BaseVidros[[Codigo]:[Preço]],3,0),"") -> 329.33 | H4: =IFERROR((C4*D4)*(G4),"") -> 255.62759 | I4: =IFERROR((C4*D4),"") -> 0.776205 | J4: =IFERROR(INDEX(BaseExtra[Código],MATCH(K4,BaseExtra[Item],0)),"") -> 1 | K4: Branca Simples | L4: =IFERROR(VLOOKUP(J4,BaseExtra[],3,0),"") -> 25 | M4: =IFERROR((C4*D4)*(L4),"") -> 19.405125 | N4: =SUM(H4,M4,) -> 275.03272 | O4: =PRODUCT(B4,N4) -> 275.03272 | P4: =SUM(O4:O11) -> 1627.0836
B5: 1 | C5: 1.05 | D5: 0.55 | E5: =IFERROR(INDEX(BaseVidros[Codigo],MATCH(F5,BaseVidros[Descrição],0)),"") -> 008787 | F5: Acidato Prata 4MM | G5: =IFERROR(VLOOKUP(E5,BaseVidros[[Codigo]:[Preço]],3,0),"") -> 271.83 | H5: =IFERROR((C5*D5)*(G5),"") -> 156.98183 | I5: =IFERROR((C5*D5),"") -> 0.5775 | J5: =IFERROR(INDEX(BaseExtra[Código],MATCH(K5,BaseExtra[Item],0)),"") | L5: =IFERROR(VLOOKUP(J5,BaseExtra[],3,0),"") | M5: =IFERROR((C5*D5)*(L5),"") | N5: =SUM(H5,M5,) -> 156.98183 | O5: =PRODUCT(B5,N5) -> 156.98183
B6: 1 | C6: 0.47 | D6: 2.2 | E6: =IFERROR(INDEX(BaseVidros[Codigo],MATCH(F6,BaseVidros[Descrição],0)),"") -> 011351 | F6: Coverglass Preto 4MM | G6: =IFERROR(VLOOKUP(E6,BaseVidros[[Codigo]:[Preço]],3,0),"") -> 188.7 | H6: =IFERROR((C6*D6)*(G6),"") -> 195.1158 | I6: =IFERROR((C6*D6),"") -> 1.034 | J6: =IFERROR(INDEX(BaseExtra[Código],MATCH(K6,BaseExtra[Item],0)),"") | L6: =IFERROR(VLOOKUP(J6,BaseExtra[],3,0),"") | M6: =IFERROR((C6*D6)*(L6),"") | N6: =SUM(H6,M6,) -> 195.1158 | O6: =PRODUCT(B6,N6) -> 195.1158
B7: 1 | C7: 0.1 | D7: 0.89 | E7: =IFERROR(INDEX(BaseVidros[Codigo],MATCH(F7,BaseVidros[Descrição],0)),"") -> 003183 | F7: Espelho Prata Cebrace | G7: =IFERROR(VLOOKUP(E7,BaseVidros[[Codigo]:[Preço]],3,0),"") -> 179.82 | H7: =IFERROR((C7*D7)*(G7),"") -> 16.00398 | I7: =IFERROR((C7*D7),"") -> 0.089 | J7: =IFERROR(INDEX(BaseExtra[Código],MATCH(K7,BaseExtra[Item],0)),"") -> 7 | K7: Jato (+ R$ 50,00) | L7: =IFERROR(VLOOKUP(J7,BaseExtra[],3,0),"") -> 113 | M7: =IFERROR((C7*D7)*(L7),"") -> 10.057 | N7: =SUM(H7,M7,) -> 26.06098 | O7: =PRODUCT(B7,N7) -> 26.06098 | Q7: 3
B8: 1 | C8: 2.1 | D8: 0.5 | E8: =IFERROR(INDEX(BaseVidros[Codigo],MATCH(F8,BaseVidros[Descrição],0)),"") -> 003184 | F8: Refletivo Champanhe 4MM | G8: =IFERROR(VLOOKUP(E8,BaseVidros[[Codigo]:[Preço]],3,0),"") -> 179.26 | H8: =IFERROR((C8*D8)*(G8),"") -> 188.223 | I8: =IFERROR((C8*D8),"") -> 1.05 | J8: =IFERROR(INDEX(BaseExtra[Código],MATCH(K8,BaseExtra[Item],0)),"") -> 9 | K8: Só Corte | L8: =IFERROR(VLOOKUP(J8,BaseExtra[],3,0),"") -> -5 | M8: =IFERROR((C8*D8)*(L8),"") -> -5.25 | N8: =SUM(H8,M8,) -> 182.973 | O8: =PRODUCT(B8,N8) -> 182.973
B9: 1 | C9: 0.885 | D9: 2.45 | E9: =IFERROR(INDEX(BaseVidros[Codigo],MATCH(F9,BaseVidros[Descrição],0)),"") -> 001106 | F9: Incolor 6MM | G9: =IFERROR(VLOOKUP(E9,BaseVidros[[Codigo]:[Preço]],3,0),"") -> 163.4 | H9: =IFERROR((C9*D9)*(G9),"") -> 354.29205 | I9: =IFERROR((C9*D9),"") -> 2.16825 | J9: =IFERROR(INDEX(BaseExtra[Código],MATCH(K9,BaseExtra[Item],0)),"") | L9: =IFERROR(VLOOKUP(J9,BaseExtra[],3,0),"") | M9: =IFERROR((C9*D9)*(L9),"") | N9: =SUM(H9,M9,) -> 354.29205 | O9: =PRODUCT(B9,N9) -> 354.29205
B10: 1 | C10: 0.655 | D10: 0.983 | E10: =IFERROR(INDEX(BaseVidros[Codigo],MATCH(F10,BaseVidros[Descrição],0)),"") -> 003650 | F10: Espelho Prata Guardian | G10: =IFERROR(VLOOKUP(E10,BaseVidros[[Codigo]:[Preço]],3,0),"") -> 187.59 | H10: =IFERROR((C10*D10)*(G10),"") -> 120.78264 | I10: =IFERROR((C10*D10),"") -> 0.643865 | J10: =IFERROR(INDEX(BaseExtra[Código],MATCH(K10,BaseExtra[Item],0)),"") -> 7 | K10: Jato (+ R$ 50,00) | L10: =IFERROR(VLOOKUP(J10,BaseExtra[],3,0),"") -> 113 | M10: =IFERROR((C10*D10)*(L10),"") -> 72.756745 | N10: =SUM(H10,M10,) -> 193.53938 | O10: =PRODUCT(B10,N10) -> 193.53938
B11: 1 | C11: 0.994 | D11: 1.36 | E11: =IFERROR(INDEX(BaseVidros[Codigo],MATCH(F11,BaseVidros[Descrição],0)),"") -> 003183 | F11: Espelho Prata Cebrace | G11: =IFERROR(VLOOKUP(E11,BaseVidros[[Codigo]:[Preço]],3,0),"") -> 179.82 | H11: =IFERROR((C11*D11)*(G11),"") -> 243.08787 | I11: =IFERROR((C11*D11),"") -> 1.35184 | J11: =IFERROR(INDEX(BaseExtra[Código],MATCH(K11,BaseExtra[Item],0)),"") | L11: =IFERROR(VLOOKUP(J11,BaseExtra[],3,0),"") | M11: =IFERROR((C11*D11)*(L11),"") | N11: =SUM(H11,M11,) -> 243.08787 | O11: =PRODUCT(B11,N11) -> 243.08787
G13: C. Moeda | H13: 30 | K13: Mão de obra Jateado | L13: 50
G14: C. Garrafa | H14: 50 | K14: Furo Tomada | L14: 40 | N14: Extra
G15: Molde | H15: 0.6 | K15: Furo 8mm a 12mm | L15: 8
K16: Furo 15mm a 60mm | L16: 15
K17: Furo 65mm a 110mm | L17: 26
